Workbook

Sheet 시나리오
A1: 배터리 주문 관리 — E2E 테스트 시나리오 (팀 통합본)
A2: 작성: 팀 통합 (SangwooSong, KewryByun, ctkim1005, sy9169) · 개인별 시나리오 72개를 중복 제거해 36개로 정리 · 담당자는 GitHub 아이디 | G2: 시나리오당 예상시간 기준(초) → | H2: 20
A4: No. | B4: 영역 | C4: 시나리오 | D4: 절차 | E4: 목적 | F4: 예상시간 | G4: Pass 조건 | H4: 담당자
A5: 1 | B5: 로그인 | C5: 올바른 계정으로 로그인하면 주문 목록으로 이동 | D5: [사전 조건] 로그아웃 상태 1. /login 접속 2. 아이디 admin, 비밀번호 admin 입력 3. 로그인 클릭 | E5: 올바른 계정으로 로그인하면 업무 화면으로 진입하는지 확인 | F5: 8 | G5: - /orders 로 이동 - '주문 목록' 제목과 '주문 추가' 버튼 표시 - 상단에 사용자명 'admin' 과 '로그아웃' 버튼 표시 | H5: kewrybyun0119
A6: 2 | B6: 로그인 | C6: 잘못된 계정 정보로 로그인 실패 | D6: [사전 조건] 로그아웃 상태 1. 아이디 admin, 틀린 비밀번호로 로그인 2. 틀린 아이디, 비밀번호 admin 으로 로그인 | E6: 잘못된 계정 정보가 거부되고 이유가 안내되는지 확인 | F6: 10 | G6: - 두 경우 모두 로그인 화면 유지 (주소에 ;jsessionid=… 가 붙는 것은 허용) - '아이디 또는 비밀번호가 올바르지 않습니다' 표시 - /orders 로 이동하지 않음 | H6: sy9169park
A7: 3 | B7: 접근 통제 | C7: 로그인 없이, 로그아웃 후 보호 기능 접근 차단 | D7: [사전 조건] 로그아웃 상태(새 브라우저 컨텍스트) 1. /orders, /orders/new, /master 를 차례로 접속 2. 로그인 없이 POST /api/simulate 요청 3. admin / admin 으로 로그인한 뒤 '로그아웃' 클릭, /orders 에 다시 접속 | E7: 세션이 없거나 끝난 뒤에는 어떤 화면과 데이터도 열리지 않는지 확인 | F7: 10 | G7: - 1, 3: /login 으로 이동하고 주문 정보가 보이지 않음 - 2: HTTP 401 로 거절 | H7: ctkim1005
A8: 4 | B8: 로그인 | C8: 로그인 상태에서 /login 또는 / 접속 시 주문 목록으로 이동 | D8: [사전 조건] 로그인 상태 1. /login 접속 2. / 접속 | E8: 이미 로그인한 사용자가 로그인 화면을 거치지 않고 목록으로 안내되는지 확인 | F8: 8 | G8: - 두 경우 모두 /orders 로 이동 | H8: ssw60040-prog
A9: 5 | B9: 공통 화면 | C9: 상단 메뉴로 화면 이동과 현재 메뉴 강조 | D9: [사전 조건] 로그인 상태 1. '주문 추가' 클릭 2. '마스터 데이터' 클릭 3. '주문 목록' 클릭 4. 로고('배터리 주문 관리') 클릭 | E9: 상단 메뉴로 주요 화면을 오갈 수 있고 현재 위치가 표시되는지 확인 | F9: 15 | G9: - 각각 /orders/new, /master, /orders, /orders 로 이동 - 현재 화면의 메뉴가 강조(active) 표시 | H9: kewrybyun0119
A10: 6 | B10: 주문 추가·시뮬레이션 | C10: 기본 수량(12,000K)으로 시뮬레이션과 방문 횟수 표시 | D10: [사전 조건] 로그인 상태, 기본 마스터 데이터 1. /orders/new 접속 2. 값을 바꾸지 않고 '시뮬레이션 실행' 클릭 | E10: 기본 입력으로 경로 3가지가 계산·표시되고 필요 방문 횟수가 나오는지 확인 (핵심 기능) | F10: 15 | G10: - 초기값: 총 생산 필요 수 12,000K, 중국·일본·베트남·인도네시아 각 3,000K - 경로안 3개 표시: 운항비 최소 / 가장 빠르게 / 가까운 곳부터 (각각 소요일·총 비용), 기본 선택은 '운항비 최소' - 지도 애니메이션 영역, 상세 표, '3. 주문 확정' 영역 표시 - 필요 방문 횟수: 일본 2회, 중국·베트남·인도네시아 각 1회 | H10: ctkim1005
A11: 7 | B11: 주문 추가·시뮬레이션 | C11: 총 생산 필요 수 변경 시 4개국 균등 분배, 잘못된 값은 이전 값으로 복구 | D11: [사전 조건] /orders/new 화면 1. 총 생산 필요 수에 10000 입력(change) 2. 10001 입력 3. 0 입력 4. 입력칸을 비움 | E11: 총 수량을 바꾸면 4개국에 균등 분배되고, 잘못된 값(0·빈 값)은 직전 값으로 복구되는지 확인 | F11: 15 | G11: - 10000 → 각 2,500K - 10001 → 중국 2,501K, 나머지 2,500K (나머지는 앞 나라부터 1씩 배분) - 0·빈 값은 입력칸이 직전 값으로 되돌아가고 게이지 값은 변하지 않음 - 합계는 항상 총 생산 필요 수와 같음 | H11: sy9169park
A12: 8 | B12: 주문 추가·시뮬레이션 | C12: 수량 게이지 연동: 오른쪽 나라가 반대로 조정 | D12: [사전 조건] 기본값 12,000K (각 3,000K) 1. 중국 수량 입력칸에 4000 입력 2. 인도네시아 수량 입력칸에 1000 입력 | E12: 한 나라의 수량을 바꾸면 인접한 나라가 반대로 조정되고 합계가 유지되는지 확인 | F12: 12 | G12: - 1: 중국 4,000K, 일본 2,000K (오른쪽 나라가 반대로 조정), 베트남·인도네시아는 3,000K 그대로, 합계 12,000K 유지 - 2: 인도네시아 1,000K, 중국이 조정 (맨 오른쪽은 맨 왼쪽이 조정), 합계 12,000K 유지 | H12: kewrybyun0119
A13: 9 | B13: 주문 추가·시뮬레이션 | C13: 게이지 경계값 보정(초과·음수) | D13: [사전 조건] 기본값 12,000K 1. 중국 수량에 99999 입력 2. 중국 수량에 -5 입력 | E13: 게이지 입력의 한계값(초과·음수)이 올바르게 보정되는지 확인 | F13: 12 | G13: - 1: 중국과 일본 합(6,000K)까지만 반영 → 중국 6,000K, 일본 0K - 2: 0 미만은 0 으로 보정 → 중국 0K, 일본 6,000K - 합계는 항상 12,000K | H13: ssw60040-prog
A14: 10 | B14: 주문 추가·시뮬레이션 | C14: 수량이 0인 나라가 있어도 시뮬레이션 | D14: [사전 조건] /orders/new 화면 1. 중국 수량을 6000 으로 조정(일본 0K) 2. 시뮬레이션 실행 | E14: 주문하지 않는 나라(0K)가 있어도 계산이 정상 동작하는지 확인 | F14: 12 | G14: - 오류 없이 3개 경로안 표시 - 일본은 방문하지 않음 (결과 상세에 일본 수거 없음) - 게이지 아래 일본 '방문 0회' | H14: ctkim1005
A15: 11 | B15: 주문 추가·시뮬레이션 | C15: 경로안 선택 전환 시 화면 갱신 | D15: [사전 조건] 시뮬레이션 결과 표시 상태 1. '가장 빠르게' 클릭 2. '가까운 곳부터' 클릭 | E15: 경로안을 바꿔 가며 비교할 수 있고 화면이 선택에 맞게 갱신되는지 확인 | F15: 12 | G15: - 클릭한 경로안만 선택(강조) 상태 - 요약·상세 표·지도 애니메이션이 선택한 안으로 갱신 | H15: sy9169park
A16: 12 | B16: 주문 추가·시뮬레이션 | C16: 시뮬레이션 전에는 확정 영역 숨김, 입력을 바꾸면 이전 결과 사라짐 | D16: [사전 조건] /orders/new 최초 진입 1. 화면 확인 2. '시뮬레이션 실행' 클릭 3. 게이지 값 또는 총 생산 필요 수를 변경 | E16: 시뮬레이션 전에는 확정 단계가 노출되지 않고, 입력이 바뀌면 이전 결과로 확정되지 않는지 확인 | F16: 12 | G16: - 1: '시뮬레이션 실행' 버튼만 보이고 결과·'3. 주문 확정' 영역은 숨김 - 3: 결과 영역(경로안·확정 영역)이 숨겨짐 → 변경된 입력으로 다시 실행해야 확정 가능 | H16: kewrybyun0119
... A40: 36 | B40: 요청 형식 | C40: 깨진 요청 뒤에도 앱이 정상 동작 | D40: [사전 조건] 로그인 상태 1. POST /api/simulate 에 끝나지 않은 JSON ({"orders":) 전송 2. 존재하지 않는 나라 이름 ({"orders":{"MARS":100}}) 전송 3. 정상 수량으로 다시 시뮬레이션하고 /orders 접속 | E40: 비정상 요청이 앱을 멈추게 하거나 내부 정보를 드러내지 않는지 확인 | F40: 7 | G40: - 1, 2: HTTP 400 이고 응답에 서버 내부 정보(trace 등 오류 추적 내용)가 없음 - 3: 3가지 안이 정상으로 나오고 /orders 가 열림 ※ 현재 응답에 trace 가 포함되는 것을 확인함 (Fail 예상) | H40: ssw60040-prog

Sheet 요약
A1: 시나리오 현황 요약
A2: '시나리오' 시트의 값으로 자동 계산됩니다. 담당자나 예상시간을 바꾸면 함께 바뀝니다.
A4: 담당자 (GitHub 아이디) | B4: 시나리오 수 | C4: 예상시간 합계 | D4: 최대 예상시간 | E4: 20초 초과 건수
A5: ssw60040-prog | B5: =COUNTIF(시나리오!$H$5:$H$40,A5) -> 9 | C5: =SUMIF(시나리오!$H$5:$H$40,A5,시나리오!$F$5:$F$40) -> 126 | D5: =SUMPRODUCT(MAX((시나리오!$H$5:$H$40=A5)*시나리오!$F$5:$F$40)) -> 20 | E5: =COUNTIFS(시나리오!$H$5:$H$40,A5,시나리오!$F$5:$F$40,">"&시나리오!$H$2) -> 0
A6: kewrybyun0119 | B6: =COUNTIF(시나리오!$H$5:$H$40,A6) -> 9 | C6: =SUMIF(시나리오!$H$5:$H$40,A6,시나리오!$F$5:$F$40) -> 128 | D6: =SUMPRODUCT(MAX((시나리오!$H$5:$H$40=A6)*시나리오!$F$5:$F$40)) -> 20 | E6: =COUNTIFS(시나리오!$H$5:$H$40,A6,시나리오!$F$5:$F$40,">"&시나리오!$H$2) -> 0
A7: ctkim1005 | B7: =COUNTIF(시나리오!$H$5:$H$40,A7) -> 9 | C7: =SUMIF(시나리오!$H$5:$H$40,A7,시나리오!$F$5:$F$40) -> 126 | D7: =SUMPRODUCT(MAX((시나리오!$H$5:$H$40=A7)*시나리오!$F$5:$F$40)) -> 20 | E7: =COUNTIFS(시나리오!$H$5:$H$40,A7,시나리오!$F$5:$F$40,">"&시나리오!$H$2) -> 0
A8: sy9169park | B8: =COUNTIF(시나리오!$H$5:$H$40,A8) -> 9 | C8: =SUMIF(시나리오!$H$5:$H$40,A8,시나리오!$F$5:$F$40) -> 128 | D8: =SUMPRODUCT(MAX((시나리오!$H$5:$H$40=A8)*시나리오!$F$5:$F$40)) -> 20 | E8: =COUNTIFS(시나리오!$H$5:$H$40,A8,시나리오!$F$5:$F$40,">"&시나리오!$H$2) -> 0
A9: 합계 | B9: =SUM(B5:B8) -> 36 | C9: =SUM(C5:C8) -> 508 | D9: =MAX(D5:D8) -> 20 | E9: =SUM(E5:E8) -> 0
A11: 전체 시나리오 수 | B11: =COUNTA(시나리오!$A$5:$A$40) -> 36
A12: 담당자 미지정 | B12: =COUNTBLANK(시나리오!$H$5:$H$40) -> 0
A13: 담당자 간 시나리오 수 차이 | B13: =MAX(B5:B8)-MIN(B5:B8) -> 0
A14: 담당자 간 예상시간 합계 차이 | B14: =MAX(C5:C8)-MIN(C5:C8) -> 2
A15: 예상시간 기준 | B15: =시나리오!$H$2 -> 20
A16: 기준 충족 여부 | B16: =IF(E9=0,"충족 (모두 기준 이내)","초과 "&E9&"건") -> 충족 (모두 기준 이내)
A18: 영역별 시나리오 수
A19: 영역 | B19: 시나리오 수 | C19: 예상시간 합계
A20: 로그인 | B20: =COUNTIF(시나리오!$B$5:$B$40,A20) -> 3 | C20: =SUMIF(시나리오!$B$5:$B$40,A20,시나리오!$F$5:$F$40) -> 26
A21: 접근 통제 | B21: =COUNTIF(시나리오!$B$5:$B$40,A21) -> 1 | C21: =SUMIF(시나리오!$B$5:$B$40,A21,시나리오!$F$5:$F$40) -> 10
A22: 공통 화면 | B22: =COUNTIF(시나리오!$B$5:$B$40,A22) -> 1 | C22: =SUMIF(시나리오!$B$5:$B$40,A22,시나리오!$F$5:$F$40) -> 15
A23: 주문 추가·시뮬레이션 | B23: =COUNTIF(시나리오!$B$5:$B$40,A23) -> 8 | C23: =SUMIF(시나리오!$B$5:$B$40,A23,시나리오!$F$5:$F$40) -> 102
A24: 입력 검증 | B24: =COUNTIF(시나리오!$B$5:$B$40,A24) -> 1 | C24: =SUMIF(시나리오!$B$5:$B$40,A24,시나리오!$F$5:$F$40) -> 8
A25: 주문 확정 | B25: =COUNTIF(시나리오!$B$5:$B$40,A25) -> 5 | C25: =SUMIF(시나리오!$B$5:$B$40,A25,시나리오!$F$5:$F$40) -> 79
A26: 주문 목록 | B26: =COUNTIF(시나리오!$B$5:$B$40,A26) -> 2 | C26: =SUMIF(시나리오!$B$5:$B$40,A26,시나리오!$F$5:$F$40) -> 35
A27: 주문 상태 | B27: =COUNTIF(시나리오!$B$5:$B$40,A27) -> 6 | C27: =SUMIF(시나리오!$B$5:$B$40,A27,시나리오!$F$5:$F$40) -> 95
A28: 마스터 데이터 | B28: =COUNTIF(시나리오!$B$5:$B$40,A28) -> 8 | C28: =SUMIF(시나리오!$B$5:$B$40,A28,시나리오!$F$5:$F$40) -> 131
A29: 요청 형식 | B29: =COUNTIF(시나리오!$B$5:$B$40,A29) -> 1 | C29: =SUMIF(시나리오!$B$5:$B$40,A29,시나리오!$F$5:$F$40) -> 7
A30: 영역 합계 | B30: =SUM(B20:B29) -> 36 | C30: =SUM(C20:C29) -> 508

Sheet 통합 내역
A1: 통합 내역 — 개인 시나리오 72개가 어디에 반영되었는가
A2: 처리: 그대로 = 1:1 반영 · 병합 = 여러 시나리오를 하나로 합침 · 분산 = 한 시나리오가 여러 통합 시나리오에 나뉨 · 제외 = 반영하지 않음
A4: 작성자 | B4: 원본 No. | C4: 원본 시나리오 | D4: 통합 No. | E4: 처리 | F4: 비고
A5: SangwooSong | B5: 1 | C5: 로그인 | 올바른 계정으로 로그인 | D5: 1 | E5: 병합
A6: SangwooSong | B6: 2 | C6: 로그인 | 잘못된 비밀번호로 로그인 실패 | D6: 2 | E6: 병합
A7: SangwooSong | B7: 3 | C7: 로그인 | 비로그인 상태의 화면·API 접근 차단 | D7: 3 | E7: 병합
A8: SangwooSong | B8: 4 | C8: 주문 목록 | 목록 화면 구성과 주문 추가로 이동 | D8: 20 | E8: 병합
A9: SangwooSong | B9: 5 | C9: 주문 추가·시뮬레이션 | 기본 수량(12,000K)으로 시뮬레이션 | D9: 6 | E9: 병합
A10: SangwooSong | B10: 6 | C10: 주문 추가·시뮬레이션 | 수량 게이지 연동 | D10: 8 | E10: 병합
A11: SangwooSong | B11: 7 | C11: 주문 추가·시뮬레이션 | 총 수량 상한(100,000K) 초과 오류 | D11: 13 | E11: 병합
A12: SangwooSong | B12: 8 | C12: 주문 확정 | 경로안 선택 후 메모와 함께 확정 | D12: 15 | E12: 병합
A13: SangwooSong | B13: 9 | C13: 주문 상태 | 확정 → 진행 변경 | D13: 22 | E13: 병합
A14: SangwooSong | B14: 10 | C14: 마스터 데이터 | 빈 값 저장 거부 | D14: 30 | E14: 병합
A15: KewryByun | B15: 1 | C15: 전체 흐름 | 로그인부터 주문 완료까지 한 번에 | D15: 22 | E15: 병합 | F15: 원본 예상시간 45초 → 20초 이내로 재구성
A16: KewryByun | B16: 2 | C16: 로그인 | 비로그인 상태로 보호 화면 접근 시 로그인으로 이동 | D16: 3 | E16: 병합
A17: KewryByun | B17: 3 | C17: 로그인 | 올바른 계정으로 로그인 | D17: 1 | E17: 병합
A18: KewryByun | B18: 4 | C18: 로그인 | 잘못된 계정 정보로 로그인 실패 | D18: 2 | E18: 병합
A19: KewryByun | B19: 5 | C19: 로그인 | 로그아웃 후 보호 화면 접근 차단 | D19: 3 | E19: 병합
A20: KewryByun | B20: 6 | C20: 로그인 | 로그인 상태에서 /login 접속 시 주문 목록으로 이동 | D20: 4 | E20: 병합
A21: KewryByun | B21: 7 | C21: 로그인 | 루트(/) 접속 시 주문 목록으로 이동 | D21: 4 | E21: 병합
A22: KewryByun | B22: 8 | C22: 공통 화면 | 상단 메뉴로 화면 이동 | D22: 5 | E22: 그대로
A23: KewryByun | B23: 9 | C23: 주문 추가·시뮬레이션 | 기본값으로 시뮬레이션 실행 | D23: 6 | E23: 병합 | F23: 원본 예상시간 30초 → 20초 이내로 재구성
A24: KewryByun | B24: 10 | C24: 주문 추가·시뮬레이션 | 총 생산 필요 수 변경 시 4개국 균등 분배 | D24: 7 | E24: 병합
A25: KewryByun | B25: 11 | C25: 주문 추가·시뮬레이션 | 게이지 조정 시 오른쪽 나라가 반대로 조정 | D25: 8 | E25: 병합 | F25: 원본 예상시간 25초 → 20초 이내로 재구성
A26: KewryByun | B26: 12 | C26: 주문 추가·시뮬레이션 | 게이지 경계값 처리(초과·음수) | D26: 9 | E26: 그대로
A27: KewryByun | B27: 13 | C27: 주문 추가·시뮬레이션 | 게이지 아래 방문 횟수 표시 | D27: 6 | E27: 병합
A28: KewryByun | B28: 14 | C28: 주문 추가·시뮬레이션 | 경로안 선택 전환 | D28: 11 | E28: 그대로
A29: KewryByun | B29: 15 | C29: 주문 추가·시뮬레이션 | 입력을 바꾸면 이전 결과가 사라짐 | D29: 12 | E29: 병합
A30: KewryByun | B30: 16 | C30: 주문 추가·시뮬레이션 | 총 생산 필요 수가 1 미만이면 이전 값 유지 | D30: 7 | E30: 병합
A31: KewryByun | B31: 17 | C31: 주문 추가·시뮬레이션 | 총 수량 상한(100,000K) 초과 | D31: 13 | E31: 병합 | F31: 원본 예상시간 30초 → 20초 이내로 재구성
A32: KewryByun | B32: 18 | C32: 주문 추가·시뮬레이션 | 수량이 0인 나라가 있어도 시뮬레이션 | D32: 10 | E32: 그대로 | F32: 원본 예상시간 25초 → 20초 이내로 재구성
A33: KewryByun | B33: 19 | C33: 주문 추가·시뮬레이션 | 시뮬레이션 전에는 주문 확정 영역이 보이지 않음 | D33: 12 | E33: 병합
A34: KewryByun | B34: 20 | C34: 주문 확정 | 경로안 선택 후 메모와 함께 확정 | D34: 15 | E34: 병합 | F34: 원본 예상시간 30초 → 20초 이내로 재구성
A35: KewryByun | B35: 21 | C35: 주문 확정 | 메모 없이 확정 | D35: 16 | E35: 병합
A36: KewryByun | B36: 22 | C36: 주문 확정 | 3가지 경로안 각각 확정 시 선택한 안이 저장됨 | D36: 15 | E36: 병합 | F36: 원본 예상시간 40초 → 20초 이내로 재구성
A37: KewryByun | B37: 23 | C37: 주문 확정 | 확정 직후 주문 목록에 반영 | D37: 16 | E37: 병합 | F37: 원본 예상시간 30초 → 20초 이내로 재구성
A38: KewryByun | B38: 24 | C38: 주문 확정 | 메모 입력 글자 수 제한(1,000자) | D38: 17 | E38: 병합
A39: KewryByun | B39: 25 | C39: 주문 확정 | 시뮬레이션 이후 마스터 데이터가 바뀌면 확정 거부(충돌) | D39: 18 | E39: 병합 | F39: 원본 예상시간 50초 → 20초 이내로 재구성
A40: KewryByun | B40: 26 | C40: 주문 확정 | 확정된 주문 상세에 저장된 계획 표시 | D40: 19 | E40: 그대로 | F40: 원본 예상시간 25초 → 20초 이내로 재구성
A41: KewryByun | B41: 27 | C41: 주문 목록 | 목록 화면 기본 구성 | D41: 20 | E41: 병합
...

Sheet 안내
A1: 안내 — 작성 기준과 가정
A3: 통합 원칙
B4: 4명의 시나리오를 모두 읽고, 같은 동작을 확인하는 것은 하나로 합쳤습니다. (예: 로그인 성공은 SangwooSong 1번, KewryByun 3번, ctkim1005 TC-E2E-001 앞부분이 모두 같은 내용)
B5: 시나리오 1건은 예상시간 20초 이내입니다. KewryByun 원본에서 20초를 넘던 시나리오(최대 50초)는 단계를 줄이거나 나눠서 20초 안에 끝나게 다시 구성했습니다.
B6: Pass 조건의 문구와 응답 코드는 각 작성자가 확인한 값을 그대로 썼습니다. 합치면서 더한 단계(기준값을 원래 값으로 되돌리기 등)는 절차에 적었습니다.
B7: 요약과 건수는 '시나리오' 시트에서 수식으로 계산합니다.
A8: 담당자 배정 원칙
B9: 담당자는 GitHub 아이디입니다: ssw60040-prog (SangwooSong), kewrybyun0119 (KewryByun), ctkim1005, sy9169park (sy9169).
B10: ① 한 사람당 9개로 같게 ② 예상시간 합계를 비슷하게 ③ 영역(로그인, 주문 추가, 확정, 목록, 상태, 기준값 등)이 한쪽으로 쏠리지 않게 나눴습니다.
B11: 본인이 작성한 시나리오와 담당이 달라도 됩니다. 담당자를 바꿀 때는 '시나리오' 시트의 담당자 칸만 바꾸면 요약이 자동으로 바뀝니다.
A12: 주의
B13: 예상시간은 화면 동작을 보고 잡은 추정치이며 실행으로 측정한 값이 아닙니다. Playwright 로 실행한 뒤 갱신하세요.
B14: 주문을 만들거나 기준값을 바꾸는 시나리오는 파일 DB 에 데이터가 남습니다. 기준값을 바꾸는 시나리오는 절차 끝에 원래 값으로 되돌립니다.
B15: 기준값을 바꾸는 시나리오(마스터 데이터 영역, 주문 확정의 '기준값 변경 거절')는 서로 영향을 줄 수 있어 한 번에 하나씩 실행합니다. (playwright.config.ts 는 순차 실행)
B16: 시나리오 26(취소), 27(없는 주문), 36(깨진 요청)은 현재 앱 결함 후보입니다. 지금 실행하면 Fail 이 예상되며, 26번은 PRD §10-1 / INTENT §7-1 의 결정이 필요합니다.
B17: 제외한 시나리오: KewryByun 28번(빈 목록). 주문이 0건인 상태에서만 확인되어 환경과 순서에 의존합니다.
A19: 이미 구현된 테스트와의 대응
A20: 통합 No. | B20: 구현된 테스트 코드 (src/test/e2e)
A21: 1 | B21: login.spec.ts · TC-E2E-001 (앞부분)
A22: 3 | B22: login.spec.ts · TC-E2E-001 (뒷부분), robustness.spec.ts · S1
A23: 13 | B23: robustness.spec.ts · S3
A24: 14 | B24: robustness.spec.ts · S2
A25: 17 | B25: robustness.spec.ts · S4 (화면 제한 부분은 미구현)
A26: 18 | B26: robustness.spec.ts · S7
A27: 24 | B27: robustness.spec.ts · S8
A28: 25 | B28: robustness.spec.ts · S9
A29: 27 | B29: robustness.spec.ts · S10
A30: 30 | B30: robustness.spec.ts · S6 (일부)
A31: 32 | B31: robustness.spec.ts · S6 (우회 요청 부분)
A32: 36 | B32: robustness.spec.ts · S5
A34: 코드가 없는 통합 시나리오는 담당자가 새로 구현합니다. 기존 코드는 담당자가 이어받아 통합본의 절차·Pass 조건에 맞게 조정합니다.
