Workbook

Sheet 시나리오
A1: 배터리 주문 관리 — E2E 테스트 시나리오 (초안)
A2: 작성: KewryByun · 상태: 팀 취합 전 · 노란 칸(담당자·진행 상태)은 역할 배분 때 채웁니다. 상세 가정은 '안내' 시트 참고.
A4: ID | B4: 영역 | C4: 시나리오 | D4: 유형 | E4: 우선순위 | F4: 사전 조건 | G4: 테스트 절차 | H4: 기대 결과 | I4: 자동화 메모 | J4: 담당자 | K4: 진행 상태
A5: FLOW-01 | B5: 전체 흐름 | C5: 로그인부터 주문 완료까지 한 번에 | D5: 정상 | E5: P1 | F5: 앱 최초 기동(기본 마스터 데이터) | G5: 1. admin/admin 로그인 2. 주문 추가 → 기본값(12,000K)으로 시뮬레이션 실행 3. '운항비 최소' 선택, 메모 입력 후 주문 확정 4. 상세에서 '진행(으)로 변경' → 확인 5. '완료(으)로 변경' → 확인 6. 주문 목록으로 이동 | H5: - 확정 후 상세 화면(/orders/{id})으로 이동, 상태 '확정' - 진행 → 완료로 차례로 바뀌고 '최종 상태라 더 바꿀 수 없습니다.' 표시 - 상태 이력 3건(확정·진행·완료) - 목록의 '완료' 칩 건수가 1 증가, 해당 주문 상태 '완료' | I5: 핵심 스모크. 다른 테스트와 데이터를 공유하므로 건수는 '실행 전 값 + 1'로 비교 | K5: 미착수
A6: AUTH-01 | B6: 로그인 | C6: 비로그인 상태로 보호 화면 접근 시 로그인으로 이동 | D6: 예외 | E6: P1 | F6: 로그아웃 상태(새 브라우저 컨텍스트) | G6: 1. /orders 접속 2. /orders/new, /master 도 각각 접속 | H6: - 세 경로 모두 /login 으로 이동 - 로그인 입력 화면 표시 | I6: 컨텍스트마다 쿠키가 분리되므로 별도 정리 불필요 | K6: 미착수
A7: AUTH-02 | B7: 로그인 | C7: 올바른 계정으로 로그인 | D7: 정상 | E7: P1 | F7: 로그아웃 상태 | G7: 1. /login 접속 2. 아이디 admin, 비밀번호 admin 입력 3. 로그인 클릭 | H7: - /orders 로 이동 - 상단에 사용자명 'admin' 과 '로그아웃' 버튼 표시 | K7: 미착수
A8: AUTH-03 | B8: 로그인 | C8: 잘못된 계정 정보로 로그인 실패 | D8: 예외 | E8: P1 | F8: 로그아웃 상태 | G8: 1. 아이디 admin / 비밀번호 틀린 값으로 로그인 2. 아이디 틀린 값 / 비밀번호 admin 으로 로그인 | H8: - 두 경우 모두 로그인 화면 유지 - '아이디 또는 비밀번호가 올바르지 않습니다' 표시 - /orders 로 이동하지 않음 | K8: 미착수
A9: AUTH-04 | B9: 로그인 | C9: 로그아웃 후 보호 화면 접근 차단 | D9: 정상 | E9: P1 | F9: 로그인 상태 | G9: 1. 상단 '로그아웃' 클릭 2. 브라우저에서 /orders 로 직접 이동 | H9: - /login 으로 이동 - 다시 /orders 접속 시 /login 으로 이동(세션 만료) | K9: 미착수
A10: AUTH-05 | B10: 로그인 | C10: 로그인 상태에서 /login 접속 시 주문 목록으로 이동 | D10: 경계 | E10: P3 | F10: 로그인 상태 | G10: 1. /login 접속 | H10: - /orders 로 이동 | K10: 미착수
A11: AUTH-06 | B11: 로그인 | C11: 루트(/) 접속 시 주문 목록으로 이동 | D11: 정상 | E11: P3 | F11: 로그인 상태 | G11: 1. / 접속 | H11: - /orders 로 이동 | K11: 미착수
A12: NAV-01 | B12: 공통 화면 | C12: 상단 메뉴로 화면 이동 | D12: 정상 | E12: P2 | F12: 로그인 상태 | G12: 1. '주문 추가' 클릭 2. '마스터 데이터' 클릭 3. '주문 목록' 클릭 4. 로고('배터리 주문 관리') 클릭 | H12: - 각각 /orders/new, /master, /orders, /orders 로 이동 - 현재 화면의 메뉴가 강조(active) 표시 | K12: 미착수
A13: SIM-01 | B13: 주문 추가·시뮬레이션 | C13: 기본값으로 시뮬레이션 실행 | D13: 정상 | E13: P1 | F13: 로그인 상태, 기본 마스터 데이터 | G13: 1. /orders/new 접속 2. 값을 바꾸지 않고 '시뮬레이션 실행' 클릭 | H13: - 초기값: 총 생산 필요 수 12,000K, 중국·일본·베트남·인도네시아 각 3,000K - 결과 영역 표시 - 경로안 3개 표시: 운항비 최소 / 가장 빠르게 / 가까운 곳부터 (각각 소요일·총 비용·운항비·배 척수) - 기본 선택은 '운항비 최소' - 지도 애니메이션 영역과 상세 표 표시 - '3. 주문 확정' 영역 표시 | I13: 결과 숫자(일수·비용)는 PlannerTest 가 검증하므로 E2E 에서는 표시 여부·형식 중심으로 확인 | K13: 미착수
A14: SIM-02 | B14: 주문 추가·시뮬레이션 | C14: 총 생산 필요 수 변경 시 4개국 균등 분배 | D14: 정상 | E14: P2 | F14: /orders/new 화면 | G14: 1. 총 생산 필요 수에 10000 입력(change) 2. 10001 입력 | H14: - 10000 → 각 2,500K - 10001 → 중국 2,501K, 나머지 2,500K(나머지는 앞 나라부터 1씩 배분) - 합계는 항상 총 생산 필요 수와 같음 | K14: 미착수
A15: SIM-03 | B15: 주문 추가·시뮬레이션 | C15: 게이지 조정 시 오른쪽 나라가 반대로 조정 | D15: 정상 | E15: P1 | F15: 기본값 12,000K(각 3,000K) | G15: 1. 중국 수량 입력칸에 4000 입력 2. 인도네시아 수량 입력칸에 1000 입력 | H15: - 1: 중국 4,000K, 일본 2,000K(오른쪽 나라가 반대로 조정), 합계 12,000K 유지 - 2: 인도네시아 1,000K, 중국이 조정(맨 오른쪽은 맨 왼쪽이 조정), 합계 12,000K 유지 | I15: 슬라이더(range)는 fill 이 안 되므로 숫자 입력칸으로 조작 | K15: 미착수
A16: SIM-04 | B16: 주문 추가·시뮬레이션 | C16: 게이지 경계값 처리(초과·음수) | D16: 경계 | E16: P2 | F16: 기본값 12,000K | G16: 1. 중국 수량에 99999 입력 2. 중국 수량에 -5 입력 | H16: - 1: 중국과 일본 합(6,000K)까지만 반영 → 중국 6,000K, 일본 0K - 2: 0 미만은 0 으로 보정 → 중국 0K, 일본 6,000K - 합계 항상 12,000K | K16: 미착수
A17: SIM-05 | B17: 주문 추가·시뮬레이션 | C17: 게이지 아래 방문 횟수 표시 | D17: 정상 | E17: P2 | F17: 기본 마스터 데이터(재고 상한: 중국 4,000 / 일본 2,000 / 베트남 10,000 / 인도네시아 7,000), 시뮬레이션 1회 실행 후 | G17: 1. 기본값(각 3,000K)으로 시뮬레이션 실행 2. 게이지 아래 문구 확인 | H17: - 중국 '방문 1회', 일본 '방문 2회', 베트남 '방문 1회', 인도네시아 '방문 1회' - 수량이 0인 나라는 '방문 0회' | I17: 방문 횟수 = 올림(수량 / 재고 상한). 마스터 데이터를 바꾸면 기대값도 달라짐 | K17: 미착수
A18: SIM-06 | B18: 주문 추가·시뮬레이션 | C18: 경로안 선택 전환 | D18: 정상 | E18: P1 | F18: 시뮬레이션 결과 표시 상태 | G18: 1. '가장 빠르게' 클릭 2. '가까운 곳부터' 클릭 | H18: - 클릭한 경로안만 선택(강조) 상태 - 요약·상세 표·지도 애니메이션이 선택한 안으로 갱신 | K18: 미착수
A19: SIM-07 | B19: 주문 추가·시뮬레이션 | C19: 입력을 바꾸면 이전 결과가 사라짐 | D19: 정상 | E19: P2 | F19: 시뮬레이션 결과 표시 상태 | G19: 1. 게이지 값 또는 총 생산 필요 수를 변경 | H19: - 결과 영역(경로안·확정 영역)이 숨겨짐 → 변경된 입력으로 다시 실행해야 확정 가능 | I19: 오래된 결과로 확정되는 것을 막는 동작 | K19: 미착수
A20: SIM-08 | B20: 주문 추가·시뮬레이션 | C20: 총 생산 필요 수가 1 미만이면 이전 값 유지 | D20: 경계 | E20: P2 | F20: /orders/new 화면 | G20: 1. 총 생산 필요 수에 0 입력(change) 2. 빈 값으로 지움 | H20: - 입력칸이 직전 값(12,000)으로 되돌아감 - 게이지 값 변화 없음 | K20: 미착수
A21: SIM-09 | B21: 주문 추가·시뮬레이션 | C21: 총 수량 상한(100,000K) 초과 | D21: 경계 | E21: P1 | F21: /orders/new 화면 | G21: 1. 총 생산 필요 수에 100000 입력 후 시뮬레이션 실행 2. 100001 입력 후 시뮬레이션 실행 | H21: - 100000: 정상적으로 결과 표시 - 100001: 결과 없이 '총 생산 필요 수는 100,000K 이하여야 합니다' 오류 표시 | I21: 입력칸 max 속성이 있어도 JS 는 막지 않으므로 서버 오류 메시지로 확인 | K21: 미착수
A22: SIM-10 | B22: 주문 추가·시뮬레이션 | C22: 수량이 0인 나라가 있어도 시뮬레이션 | D22: 경계 | E22: P2 | F22: /orders/new 화면 | G22: 1. 중국 수량을 6000 으로 조정(일본 0K) 2. 시뮬레이션 실행 | H22: - 오류 없이 3개 경로안 표시 - 일본은 방문하지 않음(결과 상세에 일본 수거 없음) | I22: 상세 표 구조는 구현 시 확인 | K22: 미착수
A23: SIM-11 | B23: 주문 추가·시뮬레이션 | C23: 시뮬레이션 전에는 주문 확정 영역이 보이지 않음 | D23: 정상 | E23: P2 | F23: /orders/new 최초 진입 | G23: 1. 화면 확인 | H23: - '시뮬레이션 실행' 버튼만 보이고 결과·'3. 주문 확정' 영역은 숨김 | K23: 미착수
A24: ORD-01 | B24: 주문 확정 | C24: 경로안 선택 후 메모와 함께 확정 | D24: 정상 | E24: P1 | F24: 시뮬레이션 결과 표시 상태 | G24: 1. '가장 빠르게' 선택 2. 메모에 '3분기 긴급 물량' 입력 3. '주문 확정' 클릭 | H24: - /orders/{id} 상세로 이동 - 상태 '확정', 경로 '가장 빠르게', 메모 '3분기 긴급 물량', 작성자 admin - 상태 이력 1건(이전 '-' → '확정', admin) | K24: 미착수
A25: ORD-02 | B25: 주문 확정 | C25: 메모 없이 확정 | D25: 정상 | E25: P2 | F25: 시뮬레이션 결과 표시 상태 | G25: 1. 메모를 비워 둔 채 '주문 확정' 클릭 | H25: - 확정 성공, 상세 메모 칸에 '-' 표시 | K25: 미착수
A26: ORD-03 | B26: 주문 확정 | C26: 3가지 경로안 각각 확정 시 선택한 안이 저장됨 | D26: 정상 | E26: P1 | F26: 시뮬레이션 결과 표시 상태(경로안별로 반복) | G26: 1. '운항비 최소' 확정 2. 같은 방법으로 '가장 빠르게', '가까운 곳부터' 확정 | H26: - 각 주문 상세의 '경로'가 선택한 경로안 이름과 일치 - 상세의 소요일·비용이 확정 직전 결과 화면과 일치 | I26: 데이터 기반 테스트(경로안 3종 반복)로 구현 | K26: 미착수
A27: ORD-04 | B27: 주문 확정 | C27: 확정 직후 주문 목록에 반영 | D27: 정상 | E27: P1 | F27: 주문 1건 확정 완료 | G27: 1. 주문 목록으로 이동 | H27: - 최상단에 방금 확정한 주문 표시(번호 내림차순) - 확정 일시, 총 수량(천 단위 콤마), 경로, 소요 일수, 총 비용(억원), 상태 '확정', 작성자 admin - '전체'·'확정' 칩 건수가 1 증가 | K27: 미착수
A28: ORD-05 | B28: 주문 확정 | C28: 메모 입력 글자 수 제한(1,000자) | D28: 경계 | E28: P3 | F28: 시뮬레이션 결과 표시 상태 | G28: 1. 메모에 1,001자 입력 | H28: - 입력칸이 1,000자까지만 받음(maxlength) - 확정 시 메모 1,000자로 저장 | I28: 서버 검증(1,000자 초과 시 400)은 API 테스트 영역 | K28: 미착수
A29: ORD-06 | B29: 주문 확정 | C29: 시뮬레이션 이후 마스터 데이터가 바뀌면 확정 거부(충돌) | D29: 예외 | E29: P1 | F29: 기본 마스터 데이터. 브라우저 탭 2개(같은 로그인 세션) | G29: 1. 탭 A: 주문 추가에서 시뮬레이션 실행(확정하지 않음) 2. 탭 B: 마스터 데이터에서 값 하나 변경 후 저장 3. 탭 A: '주문 확정' 클릭 | H29: - 확정되지 않음 - '시뮬레이션 이후 마스터 데이터가 바뀌었습니다. 다시 시뮬레이션해 주세요' 오류 표시 - 다시 시뮬레이션 실행 후에는 확정 성공 | I29: 같은 context 에서 page 2개 생성. 마스터를 바꾸므로 이후 테스트에 영향 → 마지막에 원복하거나 별도 실행 | K29: 미착수
A30: ORD-07 | B30: 주문 확정 | C30: 확정된 주문 상세에 저장된 계획 표시 | D30: 정상 | E30: P2 | F30: 주문 1건 확정 완료 | G30: 1. 상세 화면 확인 | H30: - 요약, 상세 표, '지도 애니메이션(저장된 계획)' 영역 표시 - 새로고침해도 같은 내용(저장된 계획 사용) | K30: 미착수
A31: LST-01 | B31: 주문 목록 | C31: 목록 화면 기본 구성 | D31: 정상 | E31: P2 | F31: 로그인 상태 | G31: 1. /orders 접속 | H31: - 제목 '주문 목록', '주문 추가' 버튼 - 필터 칩: 전체 / 확정 / 진행 / 완료 / 취소 (각 건수) - 표 헤더: 주문번호, 확정 일시, 총 수량(K), 경로, 소요 일수, 총 비용(억원), 상태, 작성자 | K31: 미착수
A32: LST-02 | B32: 주문 목록 | C32: 주문이 없을 때 빈 목록 문구 | D32: 경계 | E32: P3 | F32: 주문 0건(앱을 새로 띄운 직후 첫 테스트로 실행) | G32: 1. /orders 접속 | H32: - '주문이 없습니다.' 표시 - 전체·상태별 건수 모두 0 | I32: 테스트 순서에 의존하므로 파일 맨 앞에서 실행하거나 별도 프로젝트로 분리 | K32: 미착수
A33: LST-03 | B33: 주문 목록 | C33: 상태 필터 | D33: 정상 | E33: P1 | F33: 확정·진행·완료 상태의 주문이 각각 1건 이상 | G33: 1. '진행' 칩 클릭 2. '완료' 칩 클릭 3. '전체' 칩 클릭 | H33: - 1: 진행 상태 주문만 표시, '진행' 칩 강조, URL 에 status=IN_PROGRESS - 2: 완료 상태 주문만 표시 - 3: 모든 주문 표시 | I33: 사전 데이터는 테스트 안에서 직접 생성 | K33: 미착수
A34: LST-04 | B34: 주문 목록 | C34: 행 클릭 시 상세로 이동 | D34: 정상 | E34: P2 | F34: 주문 1건 이상 | G34: 1. 목록에서 주문 행(번호 링크가 아닌 다른 칸)을 클릭 | H34: - 해당 주문 상세(/orders/{id})로 이동 | K34: 미착수
A35: LST-05 | B35: 주문 목록 | C35: '주문 추가' 버튼으로 이동 | D35: 정상 | E35: P3 | F35: 로그인 상태 | G35: 1. 목록의 '주문 추가' 클릭 | H35: - /orders/new 로 이동 | K35: 미착수
A36: LST-06 | B36: 주문 목록 | C36: 건수 집계가 실제 목록과 일치 | D36: 정상 | E36: P2 | F36: 주문 여러 건(상태 혼합) | G36: 1. 각 칩의 건수와 필터 결과의 행 수를 비교 | H36: - 칩 건수 = 필터링된 행 수 - 전체 = 상태별 건수의 합 | K36: 미착수
A37: STS-01 | B37: 주문 상태 | C37: 확정 상태에서 가능한 변경 버튼 | D37: 정상 | E37: P1 | F37: 확정 상태 주문 | G37: 1. 상세 화면 확인 | H37: - '진행(으)로 변경', '취소(으)로 변경' 버튼만 표시 - '완료(으)로 변경' 버튼 없음(확정 → 완료 불가) | K37: 미착수
A38: STS-02 | B38: 주문 상태 | C38: 확정 → 진행 변경 | D38: 정상 | E38: P1 | F38: 확정 상태 주문 | G38: 1. '진행(으)로 변경' 클릭 2. 확인창 '진행(으)로 바꿉니다. 계속할까요?' 수락 | H38: - '상태를 '진행'(으)로 바꿨습니다' 메시지 - 배지 '진행' - 상태 이력 2건(확정 → 진행, admin) - 버튼: '완료(으)로 변경', '취소(으)로 변경' | I38: page.on('dialog') 로 확인창 처리 | K38: 미착수
A39: STS-03 | B39: 주문 상태 | C39: 진행 → 완료 변경 후 최종 상태 | D39: 정상 | E39: P1 | F39: 진행 상태 주문 | G39: 1. '완료(으)로 변경' 클릭 후 확인창 수락 | H39: - 배지 '완료' - 변경 버튼 없음, '최종 상태라 더 바꿀 수 없습니다.' 표시 - 상태 이력 3건 | K39: 미착수
A40: STS-04 | B40: 주문 상태 | C40: 확인창에서 취소하면 상태가 바뀌지 않음 | D40: 예외 | E40: P2 | F40: 확정 상태 주문 | G40: 1. '진행(으)로 변경' 클릭 2. 확인창 '취소(Dismiss)' | H40: - 상태 '확정' 유지, 이력 1건 그대로, 안내 메시지 없음 | K40: 미착수
A41: STS-05 | B41: 주문 상태 | C41: 확정 상태에서 취소 | D41: 정상 | E41: P1 | F41: 확정 상태 주문 | G41: 1. '취소(으)로 변경' 클릭 후 확인창 수락 | H41: [PPT·PRD 기준 기대] 주문이 '취소' 상태로 남고, 상세에서 배지 '취소'·'최종 상태라 더 바꿀 수 없습니다.' 표시, 목록의 '취소' 칩 건수 +1 [현재 동작] 주문이 삭제되고 삭제된 주문의 상세로 이동하다 오류 화면 발생(목록 '취소' 건수는 항상 0) | I41: 결함 후보(INTENT §6-1). 기대 결과가 확정되기 전까지 test.fixme 로 표시하거나 팀 합의 후 작성 | K41: 미착수
...

Sheet 요약
A1: 시나리오 현황 요약
A2: '시나리오' 시트의 값으로 자동 계산됩니다(수식).
A4: 영역별
A5: 영역 | B5: 건수
A6: 전체 흐름 | B6: =COUNTIF(시나리오!$B$5:$B$85,A6) -> 1
A7: 로그인 | B7: =COUNTIF(시나리오!$B$5:$B$85,A7) -> 6
A8: 공통 화면 | B8: =COUNTIF(시나리오!$B$5:$B$85,A8) -> 1
A9: 주문 추가·시뮬레이션 | B9: =COUNTIF(시나리오!$B$5:$B$85,A9) -> 11
A10: 주문 확정 | B10: =COUNTIF(시나리오!$B$5:$B$85,A10) -> 7
A11: 주문 목록 | B11: =COUNTIF(시나리오!$B$5:$B$85,A11) -> 6
A12: 주문 상태 | B12: =COUNTIF(시나리오!$B$5:$B$85,A12) -> 9
A13: 마스터 데이터 | B13: =COUNTIF(시나리오!$B$5:$B$85,A13) -> 10
A14: 합계 | B14: =SUM(B6:B13) -> 51
A16: 우선순위별
A17: 우선순위 | B17: 건수
A18: P1 | B18: =COUNTIF(시나리오!$E$5:$E$85,A18) -> 26
A19: P2 | B19: =COUNTIF(시나리오!$E$5:$E$85,A19) -> 19
A20: P3 | B20: =COUNTIF(시나리오!$E$5:$E$85,A20) -> 6
A21: 합계 | B21: =SUM(B18:B20) -> 51
A23: 유형별
A24: 유형 | B24: 건수
A25: 정상 | B25: =COUNTIF(시나리오!$D$5:$D$85,A25) -> 33
A26: 예외 | B26: =COUNTIF(시나리오!$D$5:$D$85,A26) -> 9
A27: 경계 | B27: =COUNTIF(시나리오!$D$5:$D$85,A27) -> 9
A28: 합계 | B28: =SUM(B25:B27) -> 51
A30: 진행 상태별
A31: 진행 상태 | B31: 건수
A32: 미착수 | B32: =COUNTIF(시나리오!$K$5:$K$85,A32) -> 51
A33: 작성중 | B33: =COUNTIF(시나리오!$K$5:$K$85,A33) -> 0
A34: 작성완료 | B34: =COUNTIF(시나리오!$K$5:$K$85,A34) -> 0
A35: 실행완료 | B35: =COUNTIF(시나리오!$K$5:$K$85,A35) -> 0
A36: 보류 | B36: =COUNTIF(시나리오!$K$5:$K$85,A36) -> 0
A37: 합계 | B37: =SUM(B32:B36) -> 51
A39: 담당자 미배정 | B39: =COUNTA(시나리오!$A$5:$A$85)-COUNTIF(시나리오!$J$5:$J$85,"?*") -> 51

Sheet 안내
A1: 안내 — 작성 기준과 가정
A3: 작성 기준
A4: 범위 | B4: 브라우저에서 사용자가 하는 주요 흐름(로그인, 주문 입력·시뮬레이션, 확정, 목록, 상태 변경, 마스터 데이터)을 Playwright 로 검증한다. 경로 계산의 정확한 숫자는 PlannerTest(단위 테스트)가 검증하므로, E2E 는 화면 표시·흐름·오류 메시지 중심으로 본다.
A5: 우선순위 | B5: P1: 핵심 흐름·데이터 정합성(먼저 구현) / P2: 주요 보조 기능 / P3: 경계·편의 기능
A6: 유형 | B6: 정상: 정상 흐름 / 예외: 오류·거부·충돌 / 경계: 한계값·특수 입력
A7: 근거 | B7: 화면 템플릿과 JS(order-new.js, master.html 등)와 서비스 코드를 읽고 실제 문구·동작을 기준으로 작성했다. 문구는 현재 구현 기준이므로 화면이 바뀌면 함께 수정한다.
A9: 실행 환경 (e2e/ 폴더)
A10: 앱 기동 | B10: playwright.config.ts 가 앱을 8081 포트 + 인메모리 DB 로 자동 기동한다. 개발용 8080 앱·data/battery 파일과 분리되어 있고, 실행할 때마다 기본 마스터 데이터로 시작한다.
A11: 순차 실행 | B11: 같은 DB 를 공유하므로 workers=1 로 순서대로 실행한다. 주문 건수·상태 건수는 다른 테스트의 영향을 받으므로 '실행 전 값 + 1' 같은 상대 비교를 쓰고, 필요한 주문은 테스트 안에서 직접 만든다.
A12: 마스터 원복 | B12: 마스터 데이터를 바꾸는 테스트(MST-02·07~10, ORD-06)는 끝에서 원래 값으로 되돌려야 한다. 되돌리지 않으면 이후 테스트의 기본값 기대(방문 횟수 등)가 깨진다.
A13: 브라우저 검증 | B13: 마스터 화면의 숫자 칸은 min/max 속성이 있어 0·범위 초과는 브라우저가 제출을 막는다. 서버 오류 메시지는 빈 값이나 운항비(텍스트 칸)로 확인한다.
A15: 확인 필요 (결함 후보)
A16: 취소 동작 (STS-05, 06) | B16: 현재 코드는 취소 시 주문을 삭제하고 삭제된 주문 상세로 이동하다 오류가 난다(INTENT §6-1, 임시 테스트로 확인). PPT 기준 기대 결과는 '취소 상태로 남음'. 팀 합의 전에는 test.fixme 처리.
A17: 없는 주문 접근 (STS-09) | B17: 예외 처리기가 없어 오류 화면이 될 것으로 보이나 E2E 로 직접 확인하지 않았다. 실제 응답을 확인한 뒤 기대 결과를 정한다.
A19: 제외한 것
A20: API 단독 검증 | B20: 400/401/409 응답 본문, 메모 1,000자 초과 서버 검증 등은 API 테스트(request fixture) 또는 기존 OrderFlowTests 영역으로 본다.
A21: 지도 애니메이션 | B21: 재생·타이밍은 불안정하므로 영역 표시 여부만 본다.
